Workbook
Name Stages: Definitions!$B$2:$B$8

Sheet Sales Pipeline
A1: Lead ID | B1: Customer Name | C1: Contact Person | D1: Lead Source | E1: Sales Rep | F1: Opportunity Name | G1: Stage | H1: Stage Change Date | I1: Probability (%) | J1: Expected Close Date | K1: Expected Order Volume (€) | L1: Loss Reason | M1: Industry | N1: Country | O1: Notes
A2: AL-1000 | B2: AlphaTech GmbH | C2: Contact 0 | D2: Referral | E2: Rep 3 | F2: Opportunity 0 | G2: Lost | H2: 45692 | I2: =VLOOKUP(G2,Definitions!$B:$C,2,0) -> 0 | J2: 45723 | K2: 20500 | L2: Price | M2: Finance | N2: Austria
A3: BE-1001 | B3: BetaLogics GmbH | C3: Contact 1 | D3: Outbound | E3: Rep 5 | F3: Opportunity 1 | G3: Lead | H3: 45805 | I3: =VLOOKUP(G3,Definitions!$B:$C,2,0) -> 0.05 | J3: 45840 | K3: 42700 | M3: Healthcare | N3: Austria
A4: GA-1002 | B4: GammaSolutions GmbH | C4: Contact 2 | D4: Other | E4: Rep 1 | F4: Opportunity 2 | G4: Won | H4: 45704 | I4: =VLOOKUP(G4,Definitions!$B:$C,2,0) -> 1 | J4: 45763 | K4: 41900 | M4: Finance | N4: Germany
A5: GA-1003 | B5: GammaSolutions GmbH | C5: Contact 3 | D5: Event | E5: Rep 5 | F5: Opportunity 3 | G5: Qualified | H5: 45647 | I5: =VLOOKUP(G5,Definitions!$B:$C,2,0) -> 0.1 | J5: 45668 | K5: 15700 | M5: Software | N5: Austria
A6: AL-1004 | B6: AlphaTech GmbH | C6: Contact 4 | D6: Event | E6: Rep 2 | F6: Opportunity 4 | G6: Qualified | H6: 45791 | I6: =VLOOKUP(G6,Definitions!$B:$C,2,0) -> 0.1 | J6: 45844 | K6: 26400 | M6: Software | N6: Switzerland
A7: BE-1005 | B7: BetaLogics GmbH | C7: Contact 5 | D7: Event | E7: Rep 3 | F7: Opportunity 5 | G7: Proposal | H7: 45671 | I7: =VLOOKUP(G7,Definitions!$B:$C,2,0) -> 0.25 | J7: 45710 | K7: 35500 | M7: Manufacturing | N7: Austria
A8: AL-1006 | B8: AlphaTech GmbH | C8: Contact 6 | D8: Outbound | E8: Rep 3 | F8: Opportunity 6 | G8: Won | H8: 45641 | I8: =VLOOKUP(G8,Definitions!$B:$C,2,0) -> 1 | J8: 45695 | K8: 18000 | M8: Manufacturing | N8: Germany
A9: AL-1007 | B9: AlphaTech GmbH | C9: Contact 7 | D9: Event | E9: Rep 4 | F9: Opportunity 7 | G9: Won | H9: 45660 | I9: =VLOOKUP(G9,Definitions!$B:$C,2,0) -> 1 | J9: 45697 | K9: 27900 | M9: Finance | N9: Switzerland
A10: GA-1008 | B10: GammaSolutions GmbH | C10: Contact 8 | D10: Referral | E10: Rep 5 | F10: Opportunity 8 | G10: Lost | H10: 45620 | I10: =VLOOKUP(G10,Definitions!$B:$C,2,0) -> 0 | J10: 45653 | K10: 28900 | L10: Timing | M10: Software | N10: Austria
A11: GA-1009 | B11: GammaSolutions GmbH | C11: Contact 9 | D11: Inbound | E11: Rep 2 | F11: Opportunity 9 | G11: Lead | H11: 45706 | I11: =VLOOKUP(G11,Definitions!$B:$C,2,0) -> 0.05 | J11: 45730 | K11: 41700 | M11: Finance | N11: Germany
A12: GA-1010 | B12: GammaSolutions GmbH | C12: Contact 10 | D12: Referral | E12: Rep 2 | F12: Opportunity 10 | G12: Qualified | H12: 45749 | I12: =VLOOKUP(G12,Definitions!$B:$C,2,0) -> 0.1 | J12: 45775 | K12: 14500 | M12: Manufacturing | N12: Austria
A13: GA-1011 | B13: GammaSolutions GmbH | C13: Contact 11 | D13: Other | E13: Rep 5 | F13: Opportunity 11 | G13: Proposal | H13: 45815 | I13: =VLOOKUP(G13,Definitions!$B:$C,2,0) -> 0.25 | J13: 45874 | K13: 41000 | M13: Software | N13: Switzerland
A14: AL-1012 | B14: AlphaTech GmbH | C14: Contact 12 | D14: Referral | E14: Rep 2 | F14: Opportunity 12 | G14: Lost | H14: 45657 | I14: =VLOOKUP(G14,Definitions!$B:$C,2,0) -> 0 | J14: 45695 | K14: 43400 | L14: Competitor | M14: Software | N14: Switzerland
A15: GA-1013 | B15: GammaSolutions GmbH | C15: Contact 13 | D15: Outbound | E15: Rep 3 | F15: Opportunity 13 | G15: Qualified | H15: 45646 | I15: =VLOOKUP(G15,Definitions!$B:$C,2,0) -> 0.1 | J15: 45693 | K15: 24700 | M15: Software | N15: Austria
A16: BE-1014 | B16: BetaLogics GmbH | C16: Contact 14 | D16: Website | E16: Rep 2 | F16: Opportunity 14 | G16: Lead | H16: 45777 | I16: =VLOOKUP(G16,Definitions!$B:$C,2,0) -> 0.05 | J16: 45799 | K16: 29700 | M16: Software | N16: Austria
A17: GA-1015 | B17: GammaSolutions GmbH | C17: Contact 15 | D17: Inbound | E17: Rep 4 | F17: Opportunity 15 | G17: Proposal | H17: 45664 | I17: =VLOOKUP(G17,Definitions!$B:$C,2,0) -> 0.25 | J17: 45679 | K17: 49900 | M17: Healthcare | N17: Austria
A18: GA-1016 | B18: GammaSolutions GmbH | C18: Contact 16 | D18: Outbound | E18: Rep 3 | F18: Opportunity 16 | G18: Won | H18: 45814 | I18: =VLOOKUP(G18,Definitions!$B:$C,2,0) -> 1 | J18: 45866 | K18: 36500 | M18: Software | N18: Switzerland
A19: BE-1017 | B19: BetaLogics GmbH | C19: Contact 17 | D19: Inbound | E19: Rep 4 | F19: Opportunity 17 | G19: Lead | H19: 45777 | I19: =VLOOKUP(G19,Definitions!$B:$C,2,0) -> 0.05 | J19: 45813 | K19: 35100 | M19: Manufacturing | N19: Austria
A20: GA-1018 | B20: GammaSolutions GmbH | C20: Contact 18 | D20: Website | E20: Rep 5 | F20: Opportunity 18 | G20: Qualified | H20: 45636 | I20: =VLOOKUP(G20,Definitions!$B:$C,2,0) -> 0.1 | J20: 45682 | K20: 34900 | M20: Software | N20: Austria
A21: GA-1019 | B21: GammaSolutions GmbH | C21: Contact 19 | D21: Referral | E21: Rep 5 | F21: Opportunity 19 | G21: Negotiation | H21: 45802 | I21: =VLOOKUP(G21,Definitions!$B:$C,2,0) -> 0.5 | J21: 45857 | K21: 36800 | M21: Manufacturing | N21: Germany
A22: GA-1020 | B22: GammaSolutions GmbH | C22: Contact 20 | D22: Referral | E22: Rep 1 | F22: Opportunity 20 | G22: Qualified | H22: 45756 | I22: =VLOOKUP(G22,Definitions!$B:$C,2,0) -> 0.1 | J22: 45784 | K22: 49700 | M22: Finance | N22: Germany
A23: GA-1021 | B23: GammaSolutions GmbH | C23: Contact 21 | D23: Inbound | E23: Rep 5 | F23: Opportunity 21 | G23: Qualified | H23: 45815 | I23: =VLOOKUP(G23,Definitions!$B:$C,2,0) -> 0.1 | J23: 45853 | K23: 18200 | M23: Finance | N23: Switzerland
A24: AL-1022 | B24: AlphaTech GmbH | C24: Contact 22 | D24: Referral | E24: Rep 2 | F24: Opportunity 22 | G24: Lost | H24: 45661 | I24: =VLOOKUP(G24,Definitions!$B:$C,2,0) -> 0 | J24: 45683 | K24: 27000 | L24: Competitor | M24: Software | N24: Germany
A25: AL-1023 | B25: AlphaTech GmbH | C25: Contact 23 | D25: Website | E25: Rep 2 | F25: Opportunity 23 | G25: Proposal | H25: 45731 | I25: =VLOOKUP(G25,Definitions!$B:$C,2,0) -> 0.25 | J25: 45761 | K25: 47400 | M25: Finance | N25: Switzerland
A26: GA-1024 | B26: GammaSolutions GmbH | C26: Contact 24 | D26: Referral | E26: Rep 2 | F26: Opportunity 24 | G26: Lead | H26: 45772 | I26: =VLOOKUP(G26,Definitions!$B:$C,2,0) -> 0.05 | J26: 45820 | K26: 21900 | M26: Healthcare | N26: Austria
A27: GA-1025 | B27: GammaSolutions GmbH | C27: Contact 25 | D27: Other | E27: Rep 1 | F27: Opportunity 25 | G27: Negotiation | H27: 45808 | I27: =VLOOKUP(G27,Definitions!$B:$C,2,0) -> 0.5 | J27: 45844 | K27: 20600 | M27: Finance | N27: Austria
A28: GA-1026 | B28: GammaSolutions GmbH | C28: Contact 26 | D28: Other | E28: Rep 3 | F28: Opportunity 26 | G28: Won | H28: 45672 | I28: =VLOOKUP(G28,Definitions!$B:$C,2,0) -> 1 | J28: 45707 | K28: 18700 | M28: Software | N28: Austria
A29: AL-1027 | B29: AlphaTech GmbH | C29: Contact 27 | D29: Inbound | E29: Rep 4 | F29: Opportunity 27 | G29: Qualified | H29: 45776 | I29: =VLOOKUP(G29,Definitions!$B:$C,2,0) -> 0.1 | J29: 45803 | K29: 5600 | M29: Manufacturing | N29: Switzerland
A30: BE-1028 | B30: BetaLogics GmbH | C30: Contact 28 | D30: Referral | E30: Rep 3 | F30: Opportunity 28 | G30: Lead | H30: 45751 | I30: =VLOOKUP(G30,Definitions!$B:$C,2,0) -> 0.05 | J30: 45793 | K30: 49900 | M30: Software | N30: Switzerland
A31: GA-1029 | B31: GammaSolutions GmbH | C31: Contact 29 | D31: Event | E31: Rep 4 | F31: Opportunity 29 | G31: Lead | H31: 45735 | I31: =VLOOKUP(G31,Definitions!$B:$C,2,0) -> 0.05 | J31: 45766 | K31: 20900 | M31: Software | N31: Switzerland
A32: BE-1030 | B32: BetaLogics GmbH | C32: Contact 30 | D32: Other | E32: Rep 4 | F32: Opportunity 30 | G32: Qualified | H32: 45717 | I32: =VLOOKUP(G32,Definitions!$B:$C,2,0) -> 0.1 | J32: 45772 | K32: 25400 | M32: Finance | N32: Switzerland
A33: AL-1031 | B33: AlphaTech GmbH | C33: Contact 31 | D33: Website | E33: Rep 4 | F33: Opportunity 31 | G33: Negotiation | H33: 45821 | I33: =VLOOKUP(G33,Definitions!$B:$C,2,0) -> 0.5 | J33: 45871 | K33: 9400 | M33: Software | N33: Austria
A34: AL-1032 | B34: AlphaTech GmbH | C34: Contact 32 | D34: Inbound | E34: Rep 5 | F34: Opportunity 32 | G34: Negotiation | H34: 45786 | I34: =VLOOKUP(G34,Definitions!$B:$C,2,0) -> 0.5 | J34: 45830 | K34: 47000 | M34: Software | N34: Switzerland
A35: AL-1033 | B35: AlphaTech GmbH | C35: Contact 33 | D35: Inbound | E35: Rep 4 | F35: Opportunity 33 | G35: Negotiation | H35: 45641 | I35: =VLOOKUP(G35,Definitions!$B:$C,2,0) -> 0.5 | J35: 45695 | K35: 42800 | M35: Healthcare | N35: Germany
A36: BE-1034 | B36: BetaLogics GmbH | C36: Contact 34 | D36: Referral | E36: Rep 5 | F36: Opportunity 34 | G36: Negotiation | H36: 45786 | I36: =VLOOKUP(G36,Definitions!$B:$C,2,0) -> 0.5 | J36: 45820 | K36: 18300 | M36: Software | N36: Austria
... A38: BE-1036 | B38: BetaLogics GmbH | C38: Contact 36 | D38: Other | E38: Rep 2 | F38: Opportunity 36 | G38: Proposal | H38: 45737 | I38: =VLOOKUP(G38,Definitions!$B:$C,2,0) -> 0.25 | J38: 45771 | K38: 28900 | M38: Healthcare | N38: Germany
A39: BE-1037 | B39: BetaLogics GmbH | C39: Contact 37 | D39: Inbound | E39: Rep 5 | F39: Opportunity 37 | G39: Lost | H39: 45734 | I39: =VLOOKUP(G39,Definitions!$B:$C,2,0) -> 0 | J39: 45749 | K39: 6800 | L39: Timing | M39: Manufacturing | N39: Germany
A40: GA-1038 | B40: GammaSolutions GmbH | C40: Contact 38 | D40: Website | E40: Rep 2 | F40: Opportunity 38 | G40: Lead | H40: 45700 | I40: =VLOOKUP(G40,Definitions!$B:$C,2,0) -> 0.05 | J40: 45746 | K40: 12400 | M40: Healthcare | N40: Austria
A41: AL-1039 | B41: AlphaTech GmbH | C41: Contact 39 | D41: Outbound | E41: Rep 1 | F41: Opportunity 39 | G41: Proposal | H41: 45686 | I41: =VLOOKUP(G41,Definitions!$B:$C,2,0) -> 0.25 | J41: 45713 | K41: 43200 | M41: Healthcare | N41: Switzerland
...

Sheet Definitions
A1: ID | B1: Stages | C1: Probability
A2: 1 | B2: Lead | C2: 0.05
A3: 2 | B3: Qualified | C3: 0.1
A4: 3 | B4: Proposal | C4: 0.25
A5: 4 | B5: Negotiation | C5: 0.5
A6: 5 | B6: Won | C6: 1
A7: 6 | B7: Lost | C7: 0

Sheet Instructions
A1: Instructions
A2: Instructions for Filling the Sales Pipeline Template: 1. Each row represents a single sales opportunity or lead. 2. 'Lead ID' should be a unique identifier (e.g., CRM ID or sequential number). 3. Use drop-down values for 'Stage', 'Deal Status', and 'Lead Source'. 4. 'Stage' options: Lead, Qualified, Proposal, Negotiation, Won, Lost 5. 'Deal Status' options: Open, Won, Lost 6. 'Lead Source' options: Inbound, Outbound, Referral, Event, Website, Other 7. Dates must follow the format: YYYY-MM-DD 8. 'Probability (%)' should be a number between 0 and 100. 9. 'Expected Order Volume (€)' should be a numeric value (e.g., 50000) 10. 'Loss Reason' should be filled only if 'Deal Status' is Lost. This template is designed to integrate seamlessly into Power BI. Do not change sheet names or merge cells. Avoid adding totals or formulas.
